Workbook

Sheet RESUMEN
B2: ANÁLISIS INTEGRAL DEL CLIENTE Y PROPUESTA DE ABONO
B3: Estudio Contable — Propuesta de valor para nuevos clientes
B4: 1) FICHA DEL CLIENTE
B5: Cliente | C5: MATHEU, MARCOS
B6: Nombre comercial | C6: DISTRIBUIDORA EXPRESS
B7: CUIT | C7: 20-31822115-5
B8: Condición fiscal | C8: A CONFIRMAR: carpeta dice Resp. Inscripto, pero la base lo ubica en zona Monotributo — bajar constancia de inscripción
B9: Ingresos Brutos | C9: A CONFIRMAR (sin dato en la base del estudio)
B10: Empleados declarados | C10: A confirmar en ARCA (F.931)
B11: Sitio web | C11: https://distribuidoraexpress.com.ar/
B12: Contacto | C12: A completar
B13: Fecha del diagnóstico | C13: 07/08/2026
B15: 2) SEMÁFORO DEL DIAGNÓSTICO ARCA
B16: Puntos pendientes de revisar | C16: =COUNTIF(DIAGNOSTICO!$F$4:$F$21,"Pendiente") -> 17
B17: Puntos OK | C17: =COUNTIF(DIAGNOSTICO!$F$4:$F$21,"OK") -> 0
B18: Alertas (atención) | C18: =COUNTIF(DIAGNOSTICO!$F$4:$F$21,"Alerta") -> 1
B19: Críticos (acción inmediata) | C19: =COUNTIF(DIAGNOSTICO!$F$4:$F$21,"Crítico") -> 0
B21: 3) LA PROPUESTA EN NÚMEROS (plan recomendado: PROFESIONAL)
B22: Valor de lista de todo lo incluido (por mes) | C22: =ABONO!$I$27 -> 945000
B23: Precio del abono propuesto (por mes) | C23: =ABONO!$I$29 -> 480000
B24: Ahorro para el cliente vs. contratar suelto | C24: =ABONO!$I$31 -> 465000
B25: Margen bruto estimado para el estudio | C25: =ABONO!$I$33 -> 120000
B27: 4) PRÓXIMOS PASOS
B28: 1. Completar la hoja DIAGNOSTICO ingresando a ARCA con clave fiscal (checklist guiado, 45-60 min).
B29: 2. Completar la hoja WEB revisando el sitio del cliente con la guía fiscal/comercial.
B30: 3. Ajustar precios y alcance en la hoja ABONO (celdas azules/amarillas).
B31: 4. Presentar la hoja PROPUESTA al cliente (guion de reunión en el informe DIAGNOSTICO.md).
B32: 5. Cargar el PDF que envió el cliente y clasificarlo en la hoja DOCS.
B34: LEYENDA DE COLORES
B35: Celdas amarillas: completar con datos reales
B36: Texto azul: valores de ejemplo, editables según tu lista de precios
B37: Texto verde: fórmula vinculada a otra hoja (no tocar)
B38: Texto negro: fórmulas y textos fijos (no tocar)
B40: Nota: los importes de honorarios de este archivo son EJEMPLOS para trabajar la propuesta; ajustalos a la lista de precios del estudio. Fuente de datos del cliente: base interna del estudio (Claves - MyA.xlsx en Drive) y carpeta Dropbox del cliente. Sin acceso a ARCA desde esta sesión.

Sheet DIAGNOSTICO
A1: DIAGNÓSTICO FISCAL EN ARCA — CHECKLIST GUIADO (completar con clave fiscal del cliente)
A2: Cómo usarlo: entrá a arca.gob.ar con la clave fiscal del cliente y recorré los servicios de la columna 'Dónde mirar'. Cargá Estado, Hallazgo e Impacto $. La fila 4 es un EJEMPLO del formato esperado.
A3: N° | B3: Área | C3: Dónde mirar (servicio ARCA) | D3: Qué revisar / pregunta clave | E3: Hallazgo | F3: Estado | G3: Detalle del hallazgo | H3: Impacto $ est. | I3: Oportunidad para el estudio | J3: Prioridad
A4: 1 | B4: Datos registrales | C4: Sistema Registral > Registro Tributario | D4: Estado del CUIT (activo/limitado), actividades declaradas vs. reales, domicilio fiscal, DFE constituido. | E4: Actividades AFIP no reflejan venta online (EJEMPLO) | F4: Alerta | G4: Falta actividad 479101 venta por internet (EJEMPLO) | H4: 0 | I4: Adecuación registral inmediata (quick win, sin costo p/ cliente) | J4: Alta
A5: 2 | B5: Padrón / Constancia | C5: Constancia de inscripción | D5: Impuestos activos: IVA, Ganancias, Autónomos. ¿Figura algo dado de baja de oficio? | F5: Pendiente | H5: 0 | I5: Regularización de inscripciones | J5: Alta
A6: 3 | B6: Deuda corriente | C6: Sistema de Cuentas Tributarias (CCMA) | D6: Deuda exigible por impuesto, intereses resarcitorios, saldos de libre disponibilidad sin usar. | F6: Pendiente | H6: 0 | I6: Compensaciones + plan de pagos = alivio de caja inmediato | J6: Alta
A7: 4 | B7: Presentaciones | C7: Mis DDJJ / Presentaciones | D7: DDJJ vencidas no presentadas (IVA, Ganancias, BP). Multas automáticas pendientes. | F7: Pendiente | H7: 0 | I7: Puesta al día con reducción de multas (art. 49) | J7: Alta
A8: 5 | B8: Planes de pago | C8: Mis Facilidades | D8: Planes vigentes (cuota, CBU debitado), planes caducos, deuda replanificable. | F8: Pendiente | H8: 0 | I8: Reformulación de planes / rehabilitación | J8: Media
A9: 6 | B9: Juicios / ejecuciones | C9: Consulta de juicios fiscales / SCT | D9: Boletas de deuda, agente fiscal actuante, embargos trabados sobre cuentas. | F9: Pendiente | H9: 0 | I9: Conciliación de juicios y levantamiento de embargos | J9: Alta
A10: 7 | B10: IVA | C10: Portal IVA / Libro de IVA Digital | D10: Últimos 12 períodos: saldo técnico vs. libre disponibilidad, consistencia débitos vs. facturación emitida. | F10: Pendiente | H10: 0 | I10: Recupero de crédito fiscal no computado | J10: Alta
A11: 8 | B11: Facturación | C11: Comprobantes en línea / Adm. puntos de venta | D11: Puntos de venta activos, factura electrónica vs. controlador, ¿emite por cada venta web?, talonarios CAI vigentes. | F11: Pendiente | H11: 0 | I11: Integración facturación-tienda online (servicio premium) | J11: Alta
A12: 9 | B12: Ret./Perc. sufridas | C12: Mis Retenciones / SIRE | D12: Retenciones y percepciones acumuladas de IVA y Ganancias (bancos, MercadoPago, proveedores) no computadas. | F12: Pendiente | H12: 0 | I12: Cómputo/recupero: honorario de éxito sobre lo recuperado | J12: Alta
A13: 10 | B13: Ganancias PH | C13: Ganancias Personas Humanas | D13: Última DDJJ presentada, anticipos a vencer, ¿corresponde reducción de anticipos? | F13: Pendiente | H13: 0 | I13: Reducción de anticipos = caja para el cliente | J13: Media
A14: 11 | B14: Bienes Personales | C14: Bienes Personales / REIBP | D14: Situación frente a BP, mínimo no imponible, ¿adhirió al REIBP?, valuaciones. | F14: Pendiente | H14: 0 | I14: Planificación patrimonial | J14: Media
A15: 12 | B15: Autónomos | C15: CCMA / Sistema Registral | D15: Categoría correcta según actividad e ingresos, deuda de aportes, recategorización anual hecha. | F15: Pendiente | H15: 0 | I15: Recategorización + regularización aportes (jubilación) | J15: Media
A16: 13 | B16: Empleados | C16: Simplificación Registral / F.931 (si tiene) | D16: Dotación declarada vs. real, F.931 al día, ART vigente, convenio aplicado (Comercio/Camioneros), deudas seg. social. | F16: Pendiente | H16: 0 | I16: Liquidación de sueldos dentro del abono | J16: Alta
... A21: 18 | B21: Fiscalizaciones | C21: Domicilio Fiscal Electrónico (histórico) | D21: Requerimientos/intimaciones sin responder, fiscalizaciones electrónicas abiertas, cartas de intimación. | F21: Pendiente | H21: 0 | I21: Defensa y respuesta profesional (fuera de abono) | J21: Alta
G22: IMPACTO TOTAL DETECTADO: | H22: =SUM(H4:H21) -> 0

Sheet WEB
A1: ANÁLISIS DEL SITIO WEB DESDE LA ÓPTICA DEL ESTUDIO — distribuidoraexpress.com.ar
A2: Revisar el sitio con esta guía. Cada hallazgo se convierte en un argumento de venta del abono: el estudio no solo liquida impuestos, mejora el negocio.
A3: N° | B3: Aspecto | C3: Qué mirar | D3: Por qué importa (fiscal / gestión) | E3: Hallazgo | F3: Acción propuesta al cliente | G3: Estado
A4: 1 | B4: Identidad fiscal visible | C4: Footer: razón social, CUIT, condición IVA, Formulario 960/D 'Data Fiscal' con QR de ARCA. | D4: Obligatorio para sitios con venta online; su ausencia es multable y resta confianza de compra. | F4: Publicar CUIT + QR Data Fiscal en el footer. | G4: Pendiente
A5: 2 | B5: Plataforma de e-commerce | C5: ¿Tienda Nube, WooCommerce, Mercado Shops, desarrollo propio? ¿Carrito real o catálogo? | D5: Define costos (comisiones deducibles en IVA/Ganancias) y si se puede integrar la facturación automática. | F5: Cotizar integración factura electrónica automática por venta. | G5: Pendiente
A6: 3 | B6: Medios de pago | C6: MercadoPago, transferencia, tarjeta, efectivo contra entrega. | D6: Cada procesador retiene IVA/Ganancias/IIBB (SIRTAC): hay crédito fiscal acumulado que casi nadie computa. | F6: Auditar retenciones de MP de los últimos 12 meses y computarlas. | G6: Pendiente
A7: 4 | B7: Zonas de envío | C7: ¿Entrega solo en su provincia o a todo el país? | D7: Venta interjurisdiccional habitual = obligación de Convenio Multilateral en IIBB; mal encuadre genera retenciones bancarias en exceso. | F7: Verificar encuadre local vs. CM y ajustar. | G7: Pendiente
A8: 5 | B8: Precios exhibidos | C8: ¿IVA incluido (consumidor final) o neto + IVA (mayorista)? ¿Lista B2B separada? | D8: Exhibición al consumidor debe ser precio final; a RI conviene mostrar neto. Mezclarlo confunde y hace perder margen. | F8: Separar canal mayorista (con CUIT) del minorista. | G8: Pendiente
A9: 6 | B9: Facturación de cada venta | C9: ¿El checkout pide CUIT/DNI y condición IVA? ¿Emite comprobante automático? | D9: Ventas web sin factura = riesgo de ajuste por facturación omitida (ARCA cruza pagos electrónicos vs. ventas declaradas). | F9: Facturar 100% de las ventas online, automatizado. | G9: Pendiente
A10: 7 | B10: Catálogo / rubros | C10: Rubros que realmente comercializa (almacén, bebidas, limpieza, etc.). | D10: Deben coincidir con las actividades declaradas en ARCA y con la habilitación municipal. | F10: Alinear actividades AFIP + habilitación con el catálogo. | G10: Pendiente
A11: 8 | B11: Promociones y descuentos | C11: Descuentos por cantidad, envío gratis desde $X, promos bancarias. | D11: Impactan margen; sin tablero de gestión no se sabe si la promo gana o pierde plata. | F11: Tablero mensual de margen por producto/canal (plan Profesional). | G11: Pendiente
A12: 9 | B12: Canal WhatsApp / redes | C12: ¿Cierra ventas por WhatsApp/Instagram fuera del carrito? | D12: Ventas informales sin trazabilidad: riesgo fiscal y pérdida de datos de clientes. | F12: Circuito único de pedidos con comprobante. | G12: Pendiente
A13: 10 | B13: Costos ocultos del canal | C13: Comisiones plataforma, pasarela, logística, embalaje. | D13: Todos generan crédito fiscal y gasto deducible si están bien facturados a nombre del negocio. | F13: Revisar que proveedores facturen al CUIT del negocio. | G13: Pendiente
A14: 11 | B14: Titularidad y dominio | C14: ¿El dominio .com.ar está a nombre del titular? ¿SSL vigente? | D14: El dominio es un activo; a nombre de terceros es un riesgo comercial. | F14: Regularizar titularidad en NIC.ar. | G14: Pendiente
A15: 12 | B15: Volumen aparente | C15: Cantidad de productos, reseñas, seguidores, frecuencia de publicaciones. | D15: Permite estimar facturación esperable y dimensionar el abono con datos. | F15: Cruzar volumen aparente vs. ventas declaradas (consistencia). | G15: Pendiente

Sheet ABONO
A1: CONSTRUCCIÓN DEL ABONO — MOTOR DE PRECIOS Y VALOR
B3: Parámetros (editar)
B4: Costo interno por hora del estudio (sueldos + estructura) | C4: 15000 | D4: Los importes azules son EJEMPLOS: reemplazalos por tu lista de precios.
B5: Cantidad de empleados del cliente | C5: 2 | D5: Tip de venta: el IVA de los honorarios no es costo para un RI — se lo computa como crédito fiscal.
B6: Precio liquidación de sueldo por empleado | C6: 35000
B7: Alícuota IVA sobre honorarios | C7: 0.21
A8: N° | B8: Servicio incluido | C8: Frecuencia | D8: Valor para el cliente (por qué le conviene) | E8: Horas/mes | F8: Costo interno | G8: Precio lista | H8: ESENCIAL | I8: PROFESIONAL | J8: PREMIUM
A9: 1 | B9: Liquidación y presentación de IVA | C9: Mensual | D9: DDJJ siempre al día: evita multas e intereses. | E9: 3 | F9: =E9*$C$4 -> 45000 | G9: 150000 | H9: 1 | I9: 1 | J9: 1
A10: 2 | B10: Ingresos Brutos (DPR / Conv. Multilateral) | C10: Mensual | D10: Alícuotas correctas y control de retenciones SIRCREB. | E10: 2 | F10: =E10*$C$4 -> 30000 | G10: 80000 | H10: 1 | I10: 1 | J10: 1
A11: 3 | B11: Libro IVA Digital y control de comprobantes | C11: Mensual | D11: Cruce compras/ventas: nada queda sin computar. | E11: 2 | F11: =E11*$C$4 -> 30000 | G11: 70000 | H11: 1 | I11: 1 | J11: 1
A12: 4 | B12: Autónomos: control y recategorización | C12: Mensual | D12: Aportes correctos, jubilación protegida. | E12: 0.5 | F12: =E12*$C$4 -> 7500 | G12: 20000 | H12: 1 | I12: 1 | J12: 1
A13: 5 | B13: Monitoreo DFE, vencimientos e intimaciones | C13: Mensual | D13: Ninguna notificación de ARCA sin respuesta a tiempo. | E13: 1 | F13: =E13*$C$4 -> 15000 | G13: 40000 | H13: 1 | I13: 1 | J13: 1
A14: 6 | B14: Sueldos, F.931 y cargas (según dotación) | C14: Mensual | D14: Nómina en regla: evita multas laborales carísimas. | E14: =1*$C$5 -> 2 | F14: =E14*$C$4 -> 30000 | G14: =$C$5*$C$6 -> 70000 | H14: 1 | I14: 1 | J14: 1
A15: 7 | B15: DDJJ Ganancias Personas Humanas (prorrateada) | C15: Anual | D15: Sin sorpresas en mayo: anticipos planificados. | E15: 2 | F15: =E15*$C$4 -> 30000 | G15: 60000 | H15: 1 | I15: 1 | J15: 1
A16: 8 | B16: Conciliación MercadoPago / bancos / retenciones | C16: Mensual | D16: Recuperás plata que hoy queda retenida de más. | E16: 3 | F16: =E16*$C$4 -> 45000 | G16: 120000 | H16: 0 | I16: 1 | J16: 1
A17: 9 | B17: Tablero de gestión (ventas, margen, caja) | C17: Mensual | D17: Números claros para decidir compras y precios. | E17: 4 | F17: =E17*$C$4 -> 60000 | G17: 150000 | H17: 0 | I17: 1 | J17: 1
A18: 10 | B18: Asesoría impositiva por WhatsApp (24-48 h) | C18: Mensual | D18: Un contador a un mensaje de distancia. | E18: 2 | F18: =E18*$C$4 -> 30000 | G18: 80000 | H18: 0 | I18: 1 | J18: 1
A19: 11 | B19: Bienes Personales (prorrateada) | C19: Anual | D19: Patrimonio declarado y optimizado. | E19: 1 | F19: =E19*$C$4 -> 15000 | G19: 35000 | H19: 0 | I19: 1 | J19: 1
A20: 12 | B20: Certificado MiPyME: alta y renovación | C20: Anual | D20: IVA a 90 días + menos retenciones = más caja. | E20: 0.5 | F20: =E20*$C$4 -> 7500 | G20: 25000 | H20: 0 | I20: 1 | J20: 1
A21: 13 | B21: Revisión trimestral de saldos a favor | C21: Trimestral | D21: Detección temprana de crédito recuperable. | E21: 1 | F21: =E21*$C$4 -> 15000 | G21: 45000 | H21: 0 | I21: 1 | J21: 1
A22: 14 | B22: Reunión mensual de resultados (45 min) | C22: Mensual | D22: Seguimiento como si fuéramos tu gerencia financiera. | E22: 1 | F22: =E22*$C$4 -> 15000 | G22: 60000 | H22: 0 | I22: 0 | J22: 1
A23: 15 | B23: Planificación fiscal anual escrita | C23: Anual | D23: Estrategia para pagar lo justo, con papeles. | E23: 2 | F23: =E23*$C$4 -> 30000 | G23: 70000 | H23: 0 | I23: 0 | J23: 1
A24: 16 | B24: Atención de requerimientos simples de ARCA | C24: Eventual | D24: Respuestas profesionales sin costo extra. | E24: 1 | F24: =E24*$C$4 -> 15000 | G24: 50000 | H24: 0 | I24: 0 | J24: 1
B25: Marcá con 1/0 qué servicio entra en cada plan (columnas H, I, J).
B26: RESULTADOS POR PLAN | H26: ESENCIAL | I26: PROFESIONAL | J26: PREMIUM
B27: VALOR DE LISTA mensual (suma de lo incluido) | H27: =SUMPRODUCT($G$9:$G$24,H$9:H$24) -> 490000 | I27: =SUMPRODUCT($G$9:$G$24,I$9:I$24) -> 945000 | J27: =SUMPRODUCT($G$9:$G$24,J$9:J$24) -> 1125000
B28: COSTO INTERNO mensual (horas del estudio) | H28: =SUMPRODUCT($F$9:$F$24,H$9:H$24) -> 187500 | I28: =SUMPRODUCT($F$9:$F$24,I$9:I$24) -> 360000 | J28: =SUMPRODUCT($F$9:$F$24,J$9:J$24) -> 420000
B29: PRECIO DEL ABONO (definir) | H29: 280000 | I29: 480000 | J29: 680000
B30: Total con IVA (el RI lo computa como crédito) | H30: =(H29)*(1+$C$7) -> 338800 | I30: =(I29)*(1+$C$7) -> 580800 | J30: =(J29)*(1+$C$7) -> 822800
B31: AHORRO $ vs. contratar suelto | H31: =(H27)-(H29) -> 210000 | I31: =(I27)-(I29) -> 465000 | J31: =(J27)-(J29) -> 445000
B32: Ahorro % | H32: =IFERROR(1-(H29)/(H27),0) -> 0.42857143 | I32: =IFERROR(1-(I29)/(I27),0) -> 0.49206349 | J32: =IFERROR(1-(J29)/(J27),0) -> 0.39555556
B33: MARGEN $ del estudio | H33: =(H29)-(H28) -> 92500 | I33: =(I29)-(I28) -> 120000 | J33: =(J29)-(J28) -> 260000
B34: Margen % | H34: =IFERROR(((H29)-(H28))/(H29),0) -> 0.33035714 | I34: =IFERROR(((I29)-(I28))/(I29),0) -> 0.25 | J34: =IFERROR(((J29)-(J28))/(J29),0) -> 0.38235294
B35: Recomendación: presentar los 3 planes anclando primero PREMIUM; el objetivo de cierre es PROFESIONAL.
B37: SERVICIOS FUERA DE ABONO (menú adicional — 'qué más podemos obtener')
B38: Servicio puntual | D38: Cuándo se dispara | G38: Precio desde
B39: Recupero de saldos a favor / percepciones | D39: Si el diagnóstico detecta crédito acumulado | G39: 20% de lo recuperado (honorario de éxito)
B40: Armado de plan de facilidades (Mis Facilidades) | D40: Si hay deuda exigible en CCMA | G40: 90000
B41: Conciliación de juicios de ejecución fiscal | D41: Si aparecen juicios en SCT | G41: 300000
B42: Defensa en fiscalización / requerimiento complejo | D42: Si hay fiscalización electrónica abierta | G42: 350000
...

Sheet PROPUESTA
B2: PROPUESTA DE SERVICIOS PROFESIONALES — MATHEU, MARCO (DISTRIBUIDORA EXPRESS)
B3: Preparada especialmente luego del diagnóstico integral de tu situación fiscal y de tu canal de ventas online.
B5: 1 | LO QUE ENCONTRAMOS (diagnóstico sin cargo — valor real $ ver hoja ABONO)
B6: • Completar con los 3 hallazgos más fuertes del DIAGNOSTICO (ej.: retenciones acumuladas sin computar).
B7: • Ej.: tu facturación electrónica no está integrada a la tienda online: doble trabajo y riesgo de multas.
B8: • Ej.: no tenés certificado MiPyME: estás pagando el IVA 90 días antes de lo necesario.
B10: 2 | QUÉ GANÁS EN LOS PRIMEROS 90 DÍAS (quick wins)
B11: 1. Certificado MiPyME aprobado: IVA a 90 días = alivio de caja inmediato.
B12: 2. Auditoría de retenciones de MercadoPago y bancos: computamos todo lo acumulado.
B13: 3. Encuadre correcto de Ingresos Brutos: dejás de sufrir retenciones en exceso.
B14: 4. Facturación de la tienda online ordenada e integrada.
B16: 3 | TU INVERSIÓN (elegí tu plan)
D17: ESENCIAL | E17: PROFESIONAL (recomendado) | F17: PREMIUM
C18: Valor de lista de todo lo incluido | D18: =ABONO!H27 -> 490000 | E18: =ABONO!I27 -> 945000 | F18: =ABONO!J27 -> 1125000
C19: Tu abono mensual | D19: =ABONO!H29 -> 280000 | E19: =ABONO!I29 -> 480000 | F19: =ABONO!J29 -> 680000
C20: Te ahorrás por mes | D20: =ABONO!H31 -> 210000 | E20: =ABONO!I31 -> 465000 | F20: =ABONO!J31 -> 445000
C21: Descuento vs. contratar suelto | D21: =ABONO!H32 -> 0.42857143 | E21: =ABONO!I32 -> 0.49206349 | F21: =ABONO!J32 -> 0.39555556
C23: El IVA de los honorarios lo computás como crédito fiscal: no es un costo real para tu negocio.
B25: 4 | BONOS POR DECIDIR AHORA
B26: • Diagnóstico integral ya realizado: SIN CARGO (queda tuyo aunque no avances).
B27: • Puesta al día de tu encuadre registral (actividades, domicilio, DFE): SIN CARGO en el primer mes.
B28: • Primer tablero de gestión de tu distribuidora: BONIFICADO el primer mes.
B30: 5 | NUESTRA GARANTÍA
B31: Si en los primeros 90 días el diagnóstico no identifica beneficios económicos (recuperos, ahorros o contingencias evitadas) por al menos el equivalente a 3 meses de abono, te bonificamos 1 mes completo. El riesgo lo asumimos nosotros.
B34: 6 | CONDICIONES
B35: • Propuesta válida por 15 días desde su presentación (cupo de 2 incorporaciones por mes para garantizar servicio).
B36: • Honorarios + IVA, ajuste trimestral por IPC (INDEC). Débito automático del 1 al 10 de cada mes.
B37: • Servicios puntuales fuera de abono: se cotizan antes de ejecutarse (ver menú en hoja ABONO).
B39: Siguiente paso: respondé este mensaje o escribinos por WhatsApp y arrancamos con el alta esta misma semana.

Sheet DOCS
A1: CHECKLIST DE DOCUMENTACIÓN A PEDIR AL CLIENTE
A2: N° | B2: Documento / acceso | C2: Para qué lo necesitamos | D2: Estado | E2: Observaciones
A3: 1 | B3: Constancia de inscripción (CUIT) actualizada | C3: Confirmar impuestos y actividades activas | D3: Pendiente
A4: 2 | B4: PDF que envió el cliente (clasificar: ¿qué documento es?) | C4: Está en la carpeta Dropbox del cliente — incorporar al diagnóstico | D4: Pendiente
A5: 3 | B5: DDJJ de IVA de los últimos 12 períodos | C5: Detectar saldos a favor y consistencia | D5: Pendiente
A6: 4 | B6: Última DDJJ de Ganancias y Bienes Personales | C6: Punto de partida patrimonial | D6: Pendiente
A7: 5 | B7: Extractos bancarios de los últimos 3 meses | C7: Retenciones SIRCREB y flujo real | D7: Pendiente
A8: 6 | B8: Reporte de retenciones de MercadoPago (Informes > Retenciones) | C8: Crédito fiscal acumulado a computar | D8: Pendiente
A9: 7 | B9: F.931 y nómina actual (si tiene empleados) | C9: Dimensionar liquidación de sueldos | D9: Pendiente
A10: 8 | B10: Planes de pago vigentes (Mis Facilidades) | C10: Evaluar reformulación | D10: Pendiente
A11: 9 | B11: Boletas/DDJJ de Ingresos Brutos últimas 6 | C11: Verificar encuadre local vs. Convenio Multilateral | D11: Pendiente
A12: 10 | B12: Habilitación municipal del local/depósito | C12: Regularidad de tasas | D12: Pendiente
A13: 11 | B13: Acceso de colaborador a la tienda online (no la contraseña) | C13: Auditar facturación del canal web | D13: Pendiente
A14: 12 | B14: Sistema de gestión/facturación que usa (Tango, Xubio, etc.) | C14: Integración contable | D14: Pendiente
... A16: 14 | B16: Datos de contacto: mail y WhatsApp del cliente | C16: Alta en circuito de comunicación del estudio | D16: Pendiente

Sheet LISTAS
A1: Pendiente | B1: Alta | C1: Pendiente
A2: En análisis | B2: Media | C2: Pedido
A3: OK | B3: Baja | C3: Recibido
A4: Alerta | C4: No aplica
A5: Crítico
